Workbook

Sheet Assumptions & Sources
B1: Allegiant Financial Model — Assumptions & Sources
B3: This tab documents every driver, judgment call, and data source used in the forecast, and how to use the scenario toggle.
B5: How to Use This Model
B6: • Go to the Data tab and pick Base, Upside, or Downside from the dropdown at C45 (Scenario Analysis section). Every forecast formula that depends on Fare, Passenger Growth, or Fuel Cost updates automatically.
B7: • The Sensitivity tab shows how 2030 Operating Profit moves across a range of fuel cost and passenger growth combinations, independent of which scenario is selected.
B8: • Blue text = hardcoded input you can change. Green text = a direct link to another sheet. Black text = a calculated formula - don't overwrite these or you'll break the chain.
B9: • Cell comments (small red triangles) explain every judgment call below in more detail - hover over the cell to read them.
B11: Driver / Line Item | C11: Value / Method | D11: Source or Rationale | E11: Type
B12: Historical Passenger, Third Party Products, Fixed Fee, Salaries, Fuel, Station Ops, D&A, Maintenance, Marketing, Lease Rentals, Other (2022-2024) | C12: As provided in original model | D12: Matches Allegiant Travel Co. FY2022-2024 reported figures (spot-checked Total Operating Revenue and Operating Income against stockanalysis.com / SEC 10-K data - both tie out). | E12: Hardcoded
B13: Fare (Data!C2) | C13: $220 flat, now escalated by Inflation each forecast year | D13: Original model assumption. Flagged: well above the historical implied fare of ~$127-135/passenger - see comment on Data!C2. This is the single biggest driver of forecast profit growth; worth a deliberate decision, not a default. | E13: Hardcoded (flagged)
B14: Inflation (Data!C3) | C14: 3.0% | D14: Original model assumption. Previously unused anywhere in the model; now feeds the Fare escalation. | E14: Hardcoded
B15: Fuel Cost per Gallon (Data!C4) | C15: $2.30 base, scenario-adjusted | D15: Original model assumption. | E15: Hardcoded
B16: Number of Aircraft Leased (Data!C5) | C16: 40 | D16: Original model assumption. Now actually drives the Aircraft Lease Rentals forecast (previously unused). | E16: Hardcoded
B17: Special Charges (forecast) | C17: $31.6M/yr flat (avg. of 2022 & 2023) | D17: 2024's $368.1M was one-time: accelerated depreciation from the fleet plan revision, a flight attendant CBA ratification bonus, and admin restructuring (Allegiant Q4 2024 Financial Results, PR Newswire, Feb 4, 2025). Previously modeled with RANDBETWEEN(), which made results non-reproducible. | E17: Judgment call
B18: Resort & Other Revenue growth | C18: Ramp-down: 65% (2025) declining to 8% (2030) | D18: 2024 actual jumped 16x on the Sunseeker Resort opening; naive compounding of that growth rate reached $1.5B by 2030 (bigger than Third Party Products). This ramp models a new-property curve maturing to a steady-state rate instead. | E18: Judgment call
B19: Aircraft Lease Rentals (forecast) | C19: Aircraft Count × Avg. Lease Rate × 12 | D19: Previously a flat 3-year historical average that ignored the aircraft count driver entirely. Now responds if you change Data!C5. | E19: Formula fix
B20: Interest Income / Expense / Other Non-Op (2022-2024) | C20: Historical actuals added | D20: Allegiant Travel Co. income statement, via stockanalysis.com (SEC 10-K based). | E20: Hardcoded, sourced
B21: Interest Expense growth (forecast) | C21: ~3.8%/yr (avg. 2022-2024 YoY) | D21: Consistent with the model's existing average-trend-rate methodology used elsewhere. | E21: Formula
B22: Interest Income (forecast) | C22: Held flat at FY2024 level | D22: Historical growth (2022→2023→2024) reflects the rate environment, not a business trend - extrapolating it would be misleading. Held flat pending a full cash/debt schedule. | E22: Judgment call
... B25: Scenario adjustments (Upside/Downside) | C25: Passenger growth ±2pp, Fare ±5%, Fuel Cost -10%/+15% | D25: Illustrative ranges - analyst judgment, not derived from a specific source. Adjust on the Data tab to whatever you want to defend. | E25: Judgment call

Sheet Dashboard
B1: Allegiant Financial Model — Dashboard
B3: Selected Scenario | D3: 2030 Total Revenue | F3: 2030 Operating Margin | H3: 2030 Net Margin | J3: Revenue CAGR ’24-’30
B4: =Data!$C$45 -> Base | D4: ='Income Statement'!K11 -> 3.4548836e+09 | F4: =Insights!D6 -> -0.41618227 | H4: =Insights!D7 -> -0.33687588 | J4: =Insights!D5 -> 0.054513134
B7: Chart Data (source — do not need to edit)
B8: Year | C8: ='Income Statement'!C5 -> 2022 | D8: ='Income Statement'!D5 -> 2023 | E8: ='Income Statement'!E5 -> 2024 | F8: ='Income Statement'!F5 -> 2025 | G8: ='Income Statement'!G5 -> 2026 | H8: ='Income Statement'!H5 -> 2027 | I8: ='Income Statement'!I5 -> 2028 | J8: ='Income Statement'!J5 -> 2029 | K8: ='Income Statement'!K5 -> 2030
B9: Passenger Revenue | C9: ='Income Statement'!C7 -> 2137762000 | D9: ='Income Statement'!D7 -> 2324387000 | E9: ='Income Statement'!E7 -> 2217059000 | F9: ='Income Statement'!F7 -> 2.1114257e+09 | G9: ='Income Statement'!G7 -> 2.1875609e+09 | H9: ='Income Statement'!H7 -> 2.2664414e+09 | I9: ='Income Statement'!I7 -> 2.3481662e+09 | J9: ='Income Statement'!J7 -> 2.4328379e+09 | K9: ='Income Statement'!K7 -> 2.5205628e+09
B10: Third Party Products | C10: ='Income Statement'!C8 -> 100959000 | D10: ='Income Statement'!D8 -> 112579000 | E10: ='Income Statement'!E8 -> 142128000 | F10: ='Income Statement'!F8 -> 1.6935512e+08 | G10: ='Income Statement'!G8 -> 2.0179808e+08 | H10: ='Income Statement'!H8 -> 2.4045605e+08 | I10: ='Income Statement'!I8 -> 2.8651964e+08 | J10: ='Income Statement'!J8 -> 3.4140753e+08 | K10: ='Income Statement'!K8 -> 4.0681015e+08
B11: Fixed Fee Contracts | C11: ='Income Statement'!C9 -> 60937000 | D11: ='Income Statement'!D9 -> 68548000 | E11: ='Income Statement'!E9 -> 80660000 | F11: ='Income Statement'!F9 -> 92823253 | G11: ='Income Statement'!G9 -> 1.0682068e+08 | H11: ='Income Statement'!H9 -> 1.2292888e+08 | I11: ='Income Statement'!I9 -> 1.4146614e+08 | J11: ='Income Statement'!J9 -> 1.6279875e+08 | K11: ='Income Statement'!K9 -> 1.8734824e+08
B12: Resort and Other | C12: ='Income Statement'!C10 -> 2171000 | D12: ='Income Statement'!D10 -> 4333000 | E12: ='Income Statement'!E10 -> 72742000 | F12: ='Income Statement'!F10 -> 1.2073031e+08 | G12: ='Income Statement'!G10 -> 1.7608867e+08 | H12: ='Income Statement'!H10 -> 2.302618e+08 | I12: ='Income Statement'!I10 -> 2.7793949e+08 | J12: ='Income Statement'!J10 -> 3.1312331e+08 | K12: ='Income Statement'!K10 -> 3.4016237e+08
B13: Operating Profit | C13: ='Income Statement'!C25 -> 91646000 | D13: ='Income Statement'!D25 -> 220971000 | E13: ='Income Statement'!E25 -> -239976000 | F13: ='Income Statement'!F25 -> -83279048 | G13: ='Income Statement'!G25 -> -2.2446765e+08 | H13: ='Income Statement'!H25 -> -4.1462829e+08 | I13: ='Income Statement'!I25 -> -6.6921725e+08 | J13: ='Income Statement'!J25 -> -1.0065761e+09 | K13: ='Income Statement'!K25 -> -1.4378613e+09
B14: Net Income | C14: ='Income Statement'!C33 -> 2676000 | D14: ='Income Statement'!D33 -> 118571000 | E14: ='Income Statement'!E33 -> -237386000 | F14: ='Income Statement'!F33 -> -1.1637804e+08 | G14: ='Income Statement'!G33 -> -2.2701858e+08 | H14: ='Income Statement'!H33 -> -3.7500498e+08 | I14: ='Income Statement'!I33 -> -5.7208884e+08 | J14: ='Income Statement'!J33 -> -8.3221479e+08 | K14: ='Income Statement'!K33 -> -1.1638669e+09
B15: Operating Margin % | C15: ='Income Statement'!C25/'Income Statement'!C11 -> 0.039814426 | D15: ='Income Statement'!D25/'Income Statement'!D11 -> 0.088041622 | E15: ='Income Statement'!E25/'Income Statement'!E11 -> -0.095509453 | F15: ='Income Statement'!F25/'Income Statement'!F11 -> -0.033387283 | G15: ='Income Statement'!G25/'Income Statement'!G11 -> -0.083998921 | H15: ='Income Statement'!H25/'Income Statement'!H11 -> -0.14497046 | I15: ='Income Statement'!I25/'Income Statement'!I11 -> -0.21912155 | J15: ='Income Statement'!J25/'Income Statement'!J11 -> -0.30969976 | K15: ='Income Statement'!K25/'Income Statement'!K11 -> -0.41618227
B16: Net Margin % | C16: ='Income Statement'!C33/'Income Statement'!C11 -> 0.0011625538 | D16: ='Income Statement'!D33/'Income Statement'!D11 -> 0.047242322 | E16: ='Income Statement'!E33/'Income Statement'!E11 -> -0.094478643 | F16: ='Income Statement'!F33/'Income Statement'!F11 -> -0.046656952 | G16: ='Income Statement'!G33/'Income Statement'!G11 -> -0.084953514 | H16: ='Income Statement'!H33/'Income Statement'!H11 -> -0.13111658 | I16: ='Income Statement'!I33/'Income Statement'!I11 -> -0.18731883 | J16: ='Income Statement'!J33/'Income Statement'!J11 -> -0.25605289 | K16: ='Income Statement'!K33/'Income Statement'!K11 -> -0.33687588

Sheet Data
B1: Model Drivers & Historical Inputs
B2: Fare | C2: 120
B3: Inflation | C3: 0.03
B4: Fuel Cost Per Gallon | C4: 2.3
B5: Number of Aircraft Leased | C5: 40
B10: Column1 | C10: 2022 | D10: 2023 | E10: 2024 | F10: Averages | H10: Avg Rates
B11: Operating Revenues
B12: Passenger | C12: =(2137762)*1000 -> 2137762000 | D12: =(2324387)*1000 -> 2324387000 | E12: =(2217059)*1000 -> 2217059000 | F12: =AVERAGE(Table4[[#This Row],[2022]:[2024]]) -> 2.2264027e+09
B13: Third Party Products | C13: =(100959)*1000 -> 100959000 | D13: =(112579)*1000 -> 112579000 | E13: =(142128)*1000 -> 142128000 | F13: =AVERAGE(Table4[[#This Row],[2022]:[2024]]) -> 1.1855533e+08
B14: Fixed Fee Contracts | C14: =(60937)*1000 -> 60937000 | D14: =(68548)*1000 -> 68548000 | E14: =(80660)*1000 -> 80660000 | F14: =AVERAGE(Table4[[#This Row],[2022]:[2024]]) -> 70048333 | G14: Fixed Fee Growth Rate | H14: =AVERAGE((Table4[[#This Row],[2023]]/Table4[[#This Row],[2022]])-1,(Table4[[#This Row],[2024]]/Table4[[#This Row],[2023]])-1) -> 0.1507966
B15: Resort and Other | C15: =(2171)*1000 -> 2171000 | D15: =(4333)*1000 -> 4333000 | E15: =(72742)*1000 -> 72742000 | F15: =AVERAGE(Table4[[#This Row],[2022]:[2024]]) -> 26415333
B18: Operating Expenses
B19: Salaries and Benefits | C19: =(552413)*1000 -> 552413000 | D19: =(687803)*1000 -> 687803000 | E19: =(819843)*1000 -> 819843000 | F19: =AVERAGE(Table4[[#This Row],[2022]:[2024]]) -> 6.8668633e+08 | G19: Wage Inflation | H19: =AVERAGE((Table4[[#This Row],[2023]]/Table4[[#This Row],[2022]])-1,(Table4[[#This Row],[2024]]/Table4[[#This Row],[2023]])-1) -> 0.21853097
B20: Aircraft Fuel | C20: =(814803)*1000 -> 814803000 | D20: =(695871)*1000 -> 695871000 | E20: =(627755)*1000 -> 627755000 | F20: =AVERAGE(Table4[[#This Row],[2022]:[2024]]) -> 7.1280967e+08
B21: Station Operations | C21: =(255168)*1000 -> 255168000 | D21: =(256560)*1000 -> 256560000 | E21: =(272843)*1000 -> 272843000 | F21: =AVERAGE(Table4[[#This Row],[2022]:[2024]]) -> 2.6152367e+08 | G21: Stations Ops Rate | H21: =AVERAGE((Table4[[#This Row],[2023]]/Table4[[#This Row],[2022]])-1,(Table4[[#This Row],[2024]]/Table4[[#This Row],[2023]])-1) -> 0.034460932
B22: Depreciation and amoritzation | C22: =(197542)*1000 -> 197542000 | D22: =(223130)*1000 -> 223130000 | E22: =(258251)*1000 -> 258251000 | F22: =AVERAGE(Table4[[#This Row],[2022]:[2024]]) -> 2.2630767e+08 | G22: Depreciation Rate | H22: =AVERAGE((Table4[[#This Row],[2023]]/Table4[[#This Row],[2022]])-1,(Table4[[#This Row],[2024]]/Table4[[#This Row],[2023]])-1) -> 0.14346673
B23: Maintenance and Repairs | C23: =(117814)*1000 -> 117814000 | D23: =(123802)*1000 -> 123802000 | E23: =(125430)*1000 -> 125430000 | F23: =AVERAGE(Table4[[#This Row],[2022]:[2024]]) -> 1.2234867e+08 | G23: Maintenance Inflation | H23: =AVERAGE((Table4[[#This Row],[2023]]/Table4[[#This Row],[2022]])-1,(Table4[[#This Row],[2024]]/Table4[[#This Row],[2023]])-1) -> 0.031987954
B24: Sales and Marketing | C24: =(100678)*1000 -> 100678000 | D24: =(114616)*1000 -> 114616000 | E24: =(106340)*1000 -> 106340000 | F24: =AVERAGE(Table4[[#This Row],[2022]:[2024]]) -> 1.0721133e+08
B25: Aircraft Lease Rentals | C25: =(23621)*1000 -> 23621000 | D25: =(24948)*1000 -> 24948000 | E25: =(23573)*1000 -> 23573000 | F25: =AVERAGE(Table4[[#This Row],[2022]:[2024]]) -> 24047333
B26: Other | C26: =(113532)*1000 -> 113532000 | D26: =(133501)*1000 -> 133501000 | E26: =(150399)*1000 -> 150399000 | F26: =AVERAGE(Table4[[#This Row],[2022]:[2024]]) -> 1.3247733e+08 | G26: Growth Rate | H26: =AVERAGE((Table4[[#This Row],[2023]]/Table4[[#This Row],[2022]])-1,(Table4[[#This Row],[2024]]/Table4[[#This Row],[2023]])-1) -> 0.15123228
B27: Special charges, nets of recoveries | C27: =(34612)*1000 -> 34612000 | D27: =(28645)*1000 -> 28645000 | E27: =(368131)*1000 -> 368131000 | F27: =AVERAGE(Table4[[#This Row],[2022]:[2024]]) -> 143796000
B29: Number of Passengers | C29: 16796544 | D29: 17342236 | E29: 16982836 | G29: Avg Passenger Growth | H29: =AVERAGE(($D29/$C29)-1,($E29/$D29)-1) -> 0.0058821894
B30: TPP Revenue Per Passenger | C30: =(C$13)/C$29 -> 6.0107008 | D30: =(D$13)/D$29 -> 6.4916081 | E30: =(E$13)/E$29 -> 8.3689202 | G30: Avg TPP Growth | H30: =AVERAGE(($D30/$C30)-1,($E30/$D30)-1) -> 0.18459957
B31: Resort Revenue Per Passenger | C31: =C$15/C$29 -> 0.12925278 | D31: =D$15/D$29 -> 0.24985244 | E31: =E$15/E$29 -> 4.2832658 | G31: Resort Revenue Manual Rate | H31: 0.65
B32: Gallons of Fuel Consumed | C32: 218606000 | D32: 224996000 | E32: 227345000 | G32: Fuel Consumption | H32: =AVERAGE(($D32/$C32)-1,($E32/$D32)-1) -> 0.019835428
B33: Percentage Marketing | C33: =C$24/SUM(C$12:C$15) -> 0.043738262 | D33: =D$24/SUM(D$12:D$15) -> 0.045666529 | E33: =E$24/SUM(E$12:E$15) -> 0.042322879 | F33: =F$24/SUM(F$12:F$15) -> 0.043913485
B34: Lease Rate | C34: =C$25/($C$5*12) -> 49210.417 | D34: =D$25/($C$5*12) -> 51975 | E34: =E$25/($C$5*12) -> 49110.417 | F34: =F$25/($C$5*12) -> 50098.611
B37: Special Charges — Normalized Forecast Assumption
B38: Normalized Special Charges (excludes 2024 one-time items) | C38: =AVERAGE(C27:D27) -> 31628500
B40: Resort & Other Revenue — Ramp-Down Growth Schedule (Judgment Override)
B41: Year | F41: 2025 | G41: 2026 | H41: 2027 | I41: 2028 | J41: 2029 | K41: 2030
B42: Resort Revenue Growth Rate (YoY) | F42: 0.65 | G42: 0.45 | H42: 0.3 | I42: 0.2 | J42: 0.12 | K42: 0.08
B44: Scenario Analysis
B45: Selected Scenario: | C45: Base
B46: Scenario | C46: Passenger Growth Adj (pp) | D46: Fare Adj (%) | E46: Fuel Cost Adj (%)
B47: Base | C47: 0 | D47: 0 | E47: 0
B48: Upside | C48: 0.02 | D48: 0.05 | E48: -0.1
B49: Downside | C49: -0.02 | D49: -0.05 | E49: 0.15
B51: Active Passenger Growth Adj | C51: =INDEX(C47:C49,MATCH($C$45,$B$47:$B$49,0)) -> 0
B52: Active Fare Adj | C52: =INDEX(D47:D49,MATCH($C$45,$B$47:$B$49,0)) -> 0
...

Sheet Income Statement
B1: Allegiant Base Case Income Statement Forecast
B2: 2022–2024 Actuals | 2025–2030 Forecast
C4: Actuals | F4: Forecast
B5: Year | C5: 2022 | D5: 2023 | E5: 2024 | F5: =E$5+1 -> 2025 | G5: =F$5+1 -> 2026 | H5: =G$5+1 -> 2027 | I5: =H$5+1 -> 2028 | J5: =I$5+1 -> 2029 | K5: =J$5+1 -> 2030
B6: Operating Revenues
B7: {=Data!B12:B15} -> Passenger | C7: {=Data!C12:E15} -> 2137762000 | D7: 2324387000 | E7: 2217059000 | F7: =F$35*F$44 -> 2.1114257e+09 | G7: =G$35*G$44 -> 2.1875609e+09 | H7: =H$35*H$44 -> 2.2664414e+09 | I7: =I$35*I$44 -> 2.3481662e+09 | J7: =J$35*J$44 -> 2.4328379e+09 | K7: =K$35*K$44 -> 2.5205628e+09
B8: Third Party Products | C8: 100959000 | D8: 112579000 | E8: 142128000 | F8: =F$35*F$36 -> 1.6935512e+08 | G8: =G$35*G$36 -> 2.0179808e+08 | H8: =H$35*H$36 -> 2.4045605e+08 | I8: =I$35*I$36 -> 2.8651964e+08 | J8: =J$35*J$36 -> 3.4140753e+08 | K8: =K$35*K$36 -> 4.0681015e+08
B9: Fixed Fee Contracts | C9: 60937000 | D9: 68548000 | E9: 80660000 | F9: =E$9*(1+Data!$H$14) -> 92823253 | G9: =F$9*(1+Data!$H$14) -> 1.0682068e+08 | H9: =G$9*(1+Data!$H$14) -> 1.2292888e+08 | I9: =H$9*(1+Data!$H$14) -> 1.4146614e+08 | J9: =I$9*(1+Data!$H$14) -> 1.6279875e+08 | K9: =J$9*(1+Data!$H$14) -> 1.8734824e+08
B10: Resort and Other | C10: 2171000 | D10: 4333000 | E10: 72742000 | F10: =F$35*F$37 -> 1.2073031e+08 | G10: =G$35*G$37 -> 1.7608867e+08 | H10: =H$35*H$37 -> 2.302618e+08 | I10: =I$35*I$37 -> 2.7793949e+08 | J10: =J$35*J$37 -> 3.1312331e+08 | K10: =K$35*K$37 -> 3.4016237e+08
B11: Total Operating Revenues | C11: =SUM(C$7:C$10) -> 2301829000 | D11: =SUM(D$7:D$10) -> 2509847000 | E11: =SUM(E$7:E$10) -> 2512589000 | F11: =SUM(F$7:F$10) -> 2.4943344e+09 | G11: =SUM(G$7:G$10) -> 2.6722683e+09 | H11: =SUM(H$7:H$10) -> 2.8600881e+09 | I11: =SUM(I$7:I$10) -> 3.0540915e+09 | J11: =SUM(J$7:J$10) -> 3.2501675e+09 | K11: =SUM(K$7:K$10) -> 3.4548836e+09
B13: Operating Expenses
B14: Salaries and Benefits | C14: =Data!$C19 -> 552413000 | D14: =Data!$D19 -> 687803000 | E14: =Data!$E19 -> 819843000 | F14: =E$14*(1+Data!$H$19) -> 9.9900409e+08 | G14: =F$14*(1+Data!$H$19) -> 1.2173174e+09 | H14: =G$14*(1+Data!$H$19) -> 1.483339e+09 | I14: =H$14*(1+Data!$H$19) -> 1.8074945e+09 | J14: =I$14*(1+Data!$H$19) -> 2.202488e+09 | K14: =J$14*(1+Data!$H$19) -> 2.6837998e+09
B15: Aircraft Fuel | C15: =Data!$C20 -> 814803000 | D15: =Data!$D20 -> 695871000 | E15: =Data!$E20 -> 627755000 | F15: =F$38*Data!$C$55 -> 5.3326532e+08 | G15: =G$38*Data!$C$55 -> 5.4384286e+08 | H15: =H$38*Data!$C$55 -> 5.5463022e+08 | I15: =I$38*Data!$C$55 -> 5.6563155e+08 | J15: =J$38*Data!$C$55 -> 5.7685109e+08 | K15: =K$38*Data!$C$55 -> 5.8829318e+08
B16: Station Operations | C16: =Data!$C21 -> 255168000 | D16: =Data!$D21 -> 256560000 | E16: =Data!$E21 -> 272843000 | F16: =E$16*(1+Data!$H$21) -> 2.8224542e+08 | G16: =F$16*(1+Data!$H$21) -> 2.9197186e+08 | H16: =G$16*(1+Data!$H$21) -> 3.0203349e+08 | I16: =H$16*(1+Data!$H$21) -> 3.1244184e+08 | J16: =I$16*(1+Data!$H$21) -> 3.2320888e+08 | K16: =J$16*(1+Data!$H$21) -> 3.3434696e+08
B17: Depreciation and amoritzation | C17: =Data!$C22 -> 197542000 | D17: =Data!$D22 -> 223130000 | E17: =Data!$E22 -> 258251000 | F17: =E$17*(1+Data!$H$22) -> 2.9530143e+08 | G17: =F$17*(1+Data!$H$22) -> 3.3766736e+08 | H17: =G$17*(1+Data!$H$22) -> 3.8611139e+08 | I17: =H$17*(1+Data!$H$22) -> 4.4150553e+08 | J17: =I$17*(1+Data!$H$22) -> 5.0484688e+08 | K17: =J$17*(1+Data!$H$22) -> 5.7727562e+08
B18: Maintenance and Repairs | C18: =Data!$C23 -> 117814000 | D18: =Data!$D23 -> 123802000 | E18: =Data!$E23 -> 125430000 | F18: =E$18*(1+Data!$H$23) -> 1.2944225e+08 | G18: =F$18*(1+Data!$H$23) -> 1.3358284e+08 | H18: =G$18*(1+Data!$H$23) -> 1.3785588e+08 | I18: =H$18*(1+Data!$H$23) -> 1.4226561e+08 | J18: =I$18*(1+Data!$H$23) -> 1.468164e+08 | K18: =J$18*(1+Data!$H$23) -> 1.5151275e+08
B19: Sales and Marketing | C19: =Data!$C24 -> 100678000 | D19: =Data!$D24 -> 114616000 | E19: =Data!$E24 -> 106340000 | F19: =F$11*Data!$F$33 -> 1.0953492e+08 | G19: =G$11*Data!$F$33 -> 1.1734861e+08 | H19: =H$11*Data!$F$33 -> 1.2559644e+08 | I19: =I$11*Data!$F$33 -> 1.341158e+08 | J19: =J$11*Data!$F$33 -> 1.4272618e+08 | K19: =K$11*Data!$F$33 -> 1.5171598e+08
B20: Aircraft Lease Rentals | C20: =Data!$C25 -> 23621000 | D20: =Data!$D25 -> 24948000 | E20: =Data!$E25 -> 23573000 | F20: =Data!$C$5*Data!$F$34*12 -> 24047333 | G20: =Data!$C$5*Data!$F$34*12 -> 24047333 | H20: =Data!$C$5*Data!$F$34*12 -> 24047333 | I20: =Data!$C$5*Data!$F$34*12 -> 24047333 | J20: =Data!$C$5*Data!$F$34*12 -> 24047333 | K20: =Data!$C$5*Data!$F$34*12 -> 24047333
B21: Other | C21: =Data!$C26 -> 113532000 | D21: =Data!$D26 -> 133501000 | E21: =Data!$E26 -> 150399000 | F21: =E$21*(1+Data!$H$26) -> 1.7314418e+08 | G21: =F$21*(1+Data!$H$26) -> 1.9932917e+08 | H21: =G$21*(1+Data!$H$26) -> 2.2947418e+08 | I21: =H$21*(1+Data!$H$26) -> 2.6417809e+08 | J21: =I$21*(1+Data!$H$26) -> 3.0413034e+08 | K21: =J$21*(1+Data!$H$26) -> 3.5012467e+08
B22: Special charges, nets of recoveries | C22: =Data!$C27 -> 34612000 | D22: =Data!$D27 -> 28645000 | E22: =Data!$E27 -> 368131000 | F22: =Data!$C$38 -> 31628500 | G22: =Data!$C$38 -> 31628500 | H22: =Data!$C$38 -> 31628500 | I22: =Data!$C$38 -> 31628500 | J22: =Data!$C$38 -> 31628500 | K22: =Data!$C$38 -> 31628500
B23: Total Operating Expenses | C23: =SUM(C$14:C$22) -> 2210183000 | D23: =SUM(D$14:D$22) -> 2288876000 | E23: =SUM(E$14:E$22) -> 2752565000 | F23: =SUM(F$14:F$22) -> 2.5776134e+09 | G23: =SUM(G$14:G$22) -> 2.896736e+09 | H23: =SUM(H$14:H$22) -> 3.2747164e+09 | I23: =SUM(I$14:I$22) -> 3.7233087e+09 | J23: =SUM(J$14:J$22) -> 4.2567436e+09 | K23: =SUM(K$14:K$22) -> 4.8927448e+09
B25: Operating Profit | C25: =C$11-C$23 -> 91646000 | D25: =D$11-D$23 -> 220971000 | E25: =E$11-E$23 -> -239976000 | F25: =F$11-F$23 -> -83279048 | G25: =G$11-G$23 -> -2.2446765e+08 | H25: =H$11-H$23 -> -4.1462829e+08 | I25: =I$11-I$23 -> -6.6921725e+08 | J25: =J$11-J$23 -> -1.0065761e+09 | K25: =K$11-K$23 -> -1.4378613e+09
B27: Non-Operating Items
B28: Interest Income | C28: 16470000 | D28: 46620000 | E28: 44010000 | F28: =$E$28 -> 44010000 | G28: =$E$28 -> 44010000 | H28: =$E$28 -> 44010000 | I28: =$E$28 -> 44010000 | J28: =$E$28 -> 44010000 | K28: =$E$28 -> 44010000
B29: Interest Expense | C29: 103070000 | D29: 108050000 | E29: 111060000 | F29: =E29*(1+Data!$C$58) -> 1.1528995e+08 | G29: =F29*(1+Data!$C$58) -> 1.1968101e+08 | H29: =G29*(1+Data!$C$58) -> 1.2423931e+08 | I29: =H29*(1+Data!$C$58) -> 1.2897122e+08 | J29: =I29*(1+Data!$C$58) -> 1.3388336e+08 | K29: =J29*(1+Data!$C$58) -> 1.3898258e+08
B30: Other Non-Operating Income (Expense) | C30: 90000 | D30: 490000 | E30: 1430000 | F30: =$E$30 -> 1430000 | G30: =$E$30 -> 1430000 | H30: =$E$30 -> 1430000 | I30: =$E$30 -> 1430000 | J30: =$E$30 -> 1430000 | K30: =$E$30 -> 1430000
B31: Pretax Income (Loss) | C31: =C25+C28-C29+C30 -> 5136000 | D31: =D25+D28-D29+D30 -> 160031000 | E31: =E25+E28-E29+E30 -> -305596000 | F31: =F25+F28-F29+F30 -> -1.53129e+08 | G31: =G25+G28-G29+G30 -> -2.9870866e+08 | H31: =H25+H28-H29+H30 -> -4.934276e+08 | I31: =I25+I28-I29+I30 -> -7.5274847e+08 | J31: =J25+J28-J29+J30 -> -1.0950195e+09 | K31: =K25+K28-K29+K30 -> -1.5314039e+09
B32: Income Tax Provision (Benefit) | C32: 2460000 | D32: 41460000 | E32: -68210000 | F32: =F31*Data!$C$57 -> -36750960 | G32: =G31*Data!$C$57 -> -71690079 | H32: =H31*Data!$C$57 -> -1.1842262e+08 | I32: =I31*Data!$C$57 -> -1.8065963e+08 | J32: =J31*Data!$C$57 -> -2.6280467e+08 | K32: =K31*Data!$C$57 -> -3.6753692e+08
B33: Net Income (Loss) | C33: =C31-C32 -> 2676000 | D33: =D31-D32 -> 118571000 | E33: =E31-E32 -> -237386000 | F33: =F31-F32 -> -1.1637804e+08 | G33: =G31-G32 -> -2.2701858e+08 | H33: =H31-H32 -> -3.7500498e+08 | I33: =I31-I32 -> -5.7208884e+08 | J33: =J31-J32 -> -8.3221479e+08 | K33: =K31-K32 -> -1.1638669e+09
B34: Forecast Inputs
B35: Number of Passengers | C35: {=Data!C29:E29} -> 16796544 | D35: 17342236 | E35: 16982836 | F35: =E$35*(1+Data!$C$54) -> 17082732 | G35: =F$35*(1+Data!$C$54) -> 17183216 | H35: =G$35*(1+Data!$C$54) -> 17284291 | I35: =H$35*(1+Data!$C$54) -> 17385961 | J35: =I$35*(1+Data!$C$54) -> 17488228 | K35: =J$35*(1+Data!$C$54) -> 17591097
B36: {=Data!B30:E34} -> TPP Revenue Per Passenger | C36: 6.0107008 | D36: 6.4916081 | E36: 8.3689202 | F36: =E$36*(1+Data!$H$30) -> 9.9138193 | G36: =F$36*(1+Data!$H$30) -> 11.743906 | H36: =G$36*(1+Data!$H$30) -> 13.911826 | I36: =H$36*(1+Data!$H$30) -> 16.479943 | J36: =I$36*(1+Data!$H$30) -> 19.522134 | K36: =J$36*(1+Data!$H$30) -> 23.125911
B37: Resort Revenue Per Passenger | C37: 0.12925278 | D37: 0.24985244 | E37: 4.2832658 | F37: =E$37*(1+Data!F$42) -> 7.0673885 | G37: =F$37*(1+Data!G$42) -> 10.247713 | H37: =G$37*(1+Data!H$42) -> 13.322027 | I37: =H$37*(1+Data!I$42) -> 15.986433 | J37: =I$37*(1+Data!J$42) -> 17.904805 | K37: =J$37*(1+Data!K$42) -> 19.337189
B38: Gallons of Fuel Consumed | C38: 218606000 | D38: 224996000 | E38: 227345000 | F38: =E38*(1+Data!$H$32) -> 2.3185449e+08 | G38: =F38*(1+Data!$H$32) -> 2.3645342e+08 | H38: =G38*(1+Data!$H$32) -> 2.4114357e+08 | I38: =H38*(1+Data!$H$32) -> 2.4592676e+08 | J38: =I38*(1+Data!$H$32) -> 2.5080482e+08 | K38: =J38*(1+Data!$H$32) -> 2.5577964e+08
B39: Percentage Marketing | C39: 0.043738262 | D39: 0.045666529 | E39: 0.042322879
B40: Lease Rate | C40: 49210.417 | D40: 51975 | E40: 49110.417
B41: Note: Special Charges are now held flat at the 2022-2023 average (see Data tab), excluding the 2024 one-time items. Resort and Other revenue now follows a ramp-down growth schedule instead of flat compounding (see Data tab).
B43: Fare — Inflation-Escalated Base | F43: =Data!$C$2*(1+Data!$C$3) -> 123.6 | G43: =F43*(1+Data!$C$3) -> 127.308 | H43: =G43*(1+Data!$C$3) -> 131.12724 | I43: =H43*(1+Data!$C$3) -> 135.06106 | J43: =I43*(1+Data!$C$3) -> 139.11289 | K43: =J43*(1+Data!$C$3) -> 143.28628
B44: Fare — Scenario-Adjusted (used in Passenger Revenue) | F44: =F43*(1+Data!$C$52) -> 123.6 | G44: =G43*(1+Data!$C$52) -> 127.308 | H44: =H43*(1+Data!$C$52) -> 131.12724 | I44: =I43*(1+Data!$C$52) -> 135.06106 | J44: =J43*(1+Data!$C$52) -> 139.11289 | K44: =K43*(1+Data!$C$52) -> 143.28628
B46: Shares Outstanding — Diluted (millions) | C46: 17.79 | D46: 18.7 | E46: 17.81 | F46: =$E$46 -> 17.81 | G46: =$E$46 -> 17.81 | H46: =$E$46 -> 17.81 | I46: =$E$46 -> 17.81 | J46: =$E$46 -> 17.81 | K46: =$E$46 -> 17.81
...

Sheet Insights
B1: Key Insights — Allegiant Base/Scenario Forecast
C2: Year | D2: Value
B3: Most Profitable Year — Operating Profit (Forecast) | C3: =INDEX('Income Statement'!F5:K5,MATCH(D3,'Income Statement'!F25:K25,0)) -> 2025 | D3: =MAX('Income Statement'!F25:K25) -> -83279048
B4: Least Profitable Year — Operating Profit (Forecast) | C4: =INDEX('Income Statement'!F5:K5,MATCH(D4,'Income Statement'!F25:K25,0)) -> 2030 | D4: =MIN('Income Statement'!F25:K25) -> -1.4378613e+09
B5: Total Revenue CAGR, 2024–2030 (Forecast) | C5: — | D5: =(('Income Statement'!K11/'Income Statement'!E11)^(1/6))-1 -> 0.054513134
B6: Operating Margin, 2030 (Forecast) | C6: — | D6: ='Income Statement'!K25/'Income Statement'!K11 -> -0.41618227
B7: Net Margin, 2030 (Forecast) | C7: — | D7: ='Income Statement'!K33/'Income Statement'!K11 -> -0.33687588
B8: Most Profitable Year — Net Income (Forecast) | C8: =INDEX('Income Statement'!F5:K5,MATCH(D8,'Income Statement'!F33:K33,0)) -> 2025 | D8: =MAX('Income Statement'!F33:K33) -> -1.1637804e+08
B9: Least Profitable Year — Net Income (Forecast) | C9: =INDEX('Income Statement'!F5:K5,MATCH(D9,'Income Statement'!F33:K33,0)) -> 2030 | D9: =MIN('Income Statement'!F33:K33) -> -1.1638669e+09
B11: Note: figures reflect the currently selected scenario on the Data tab (Base/Upside/Downside).

Sheet Sensitivity
B1: 2030 Operating Profit Sensitivity
B2: Fuel Cost per Gallon vs. Passenger Growth Rate
B4: Shows how 2030 Operating Profit moves if fuel cost and passenger growth land above or below the assumption currently active on the Data tab. Other revenue and expense lines are held at their 2030 values for the scenario currently selected on the Data tab (Base/Upside/Downside) - this grid isolates the two variables analysts ask about most.
B6: Passenger Growth Rate → | C6: =Data!$C$54-0.01 -> -0.0041178106 | D6: =Data!$C$54 -> 0.0058821894 | E6: =Data!$C$54+0.01 -> 0.015882189
B7: ↓ Fuel Cost / Gallon
B8: =Data!$C$55*0.85 -> 1.955 | C8: =((('Income Statement'!$E$35*(1+C$6)^6)*$C$16)+$C$14)-((($C$17)*$B8)+$C$15) -> -1.4962791e+09 | D8: =((('Income Statement'!$E$35*(1+D$6)^6)*$C$16)+$C$14)-((($C$17)*$B8)+$C$15) -> -1.3496173e+09 | E8: =((('Income Statement'!$E$35*(1+E$6)^6)*$C$16)+$C$14)-((($C$17)*$B8)+$C$15) -> -1.1954813e+09
B9: =Data!$C$55 -> 2.3 | C9: =((('Income Statement'!$E$35*(1+C$6)^6)*$C$16)+$C$14)-((($C$17)*$B9)+$C$15) -> -1.5845231e+09 | D9: =((('Income Statement'!$E$35*(1+D$6)^6)*$C$16)+$C$14)-((($C$17)*$B9)+$C$15) -> -1.4378613e+09 | E9: =((('Income Statement'!$E$35*(1+E$6)^6)*$C$16)+$C$14)-((($C$17)*$B9)+$C$15) -> -1.2837252e+09
B10: =Data!$C$55*1.15 -> 2.645 | C10: =((('Income Statement'!$E$35*(1+C$6)^6)*$C$16)+$C$14)-((($C$17)*$B10)+$C$15) -> -1.672767e+09 | D10: =((('Income Statement'!$E$35*(1+D$6)^6)*$C$16)+$C$14)-((($C$17)*$B10)+$C$15) -> -1.5261052e+09 | E10: =((('Income Statement'!$E$35*(1+E$6)^6)*$C$16)+$C$14)-((($C$17)*$B10)+$C$15) -> -1.3719692e+09
B13: Helper values (2030, current scenario)
B14: Other Revenue, ex. Passenger | C14: ='Income Statement'!K11-'Income Statement'!K7 -> 9.3432077e+08
B15: Other Opex, ex. Fuel | C15: ='Income Statement'!K23-'Income Statement'!K15 -> 4.3044516e+09
B16: Fare per Passenger, 2030 (current scenario) | C16: ='Income Statement'!K44 -> 143.28628
B17: Fuel Gallons Consumed, 2030 (base) | C17: ='Income Statement'!K38 -> 2.5577964e+08
